<robot name="arm">
    <link name="world" />
    <link name="base_link">
        <inertial>
            <mass value="1.0" />
            <origin rpy="0 0 0" xyz="0 0 0.1" />
            <inertia ixx="0.0027" iyy="0.0027" izz="0.005" ixy="0" ixz="0" iyz="0" />
        </inertial>
        <visual>
            <geometry>
                <box size="0.05 0.05 0.2" />
            </geometry>
            <material name="blue">
                <color rgba="0 1 1 1" />
            </material>
            <origin rpy="0 0 0" xyz="0 0 0.1" />
        </visual>
        <collision>
            <geometry>
                <box size="0.05 0.05 0.2" />
            </geometry>
            <origin rpy="0 0 0" xyz="0 0 0.1" />
        </collision>
    </link>
    <joint name="fixed" type="fixed">
        <parent link="world" />
        <child link="base_link" />
    </joint>
    <link name="torso">
        <inertial>
            <mass value="1.0" />
            <origin rpy="0 0 0" xyz="0 0 0" />
            <inertia ixx="0.02146" iyy="0.02146" izz="0.00125" ixy="0" ixz="0" iyz="0" />
        </inertial>
        <visual>
            <geometry>
                <box size="0.05 0.05 0.2" />
            </geometry>
            <material name="ungu">
                <color rgba="1 0 1 1" />
            </material>
            <origin rpy="0 0 0" xyz="0 0 0.075" />
        </visual>
        <collision>
            <geometry>
                <box size="0.05 0.05 0.2" />
            </geometry>
            <origin rpy="0 0 0" xyz="0 0 0.075" />
        </collision>
    </link>
    <joint name="joint1" type="revolute">
        <axis xyz="1 0 0" />
        <limit velocity="1.0" effort="30.0" upper="2.3562" lower="0" />
        <parent link="base_link" />
        <child link="torso" />
        <origin rpy="0 0 0" xyz="0 0 0.175" />
    </joint>
    <link name="upper_arm">
        <inertial>
            <mass value="1.0" />
            <origin rpy="0 0 0" xyz="0 0 0" />
            <inertia ixx="0.02146" iyy="0.02146" izz="0.00125" ixy="0" ixz="0" iyz="0" />
        </inertial>
        <visual>
            <geometry>
                <box size="0.05 0.05 0.2" />
            </geometry>
            <material name="briu">
                <color rgba="0 1 1 1" />
            </material>
            <origin rpy="0 0 0" xyz="0 0 0.075" />
        </visual>
        <collision>
            <geometry>
                <box size="0.05 0.05 0.2" />
            </geometry>
            <origin rpy="0 0 0" xyz="0 0 0.075" />
        </collision>
    </link>
    <joint name="joint2" type="revolute">
        <axis xyz="1 0 0" />
        <limit velocity="1.0" effort="30.0" upper="0" lower="-1.5708" />
        <parent link="torso" />
        <child link="upper_arm" />
        <origin rpy="0 0 0" xyz="0 0 0.15" />
    </joint>
    <link name="forearm">
        <inertial>
            <mass value="1.0" />
            <origin rpy="0 0 0" xyz="0 0 0.1" />
            <inertia ixx="0.0027" iyy="0.0027" izz="0.005" ixy="0" ixz="0" iyz="0" />
        </inertial>
        <visual>
            <geometry>
                <box size="0.05 0.05 0.2" />
            </geometry>
            <material name="ungu">
                <color rgba="1 0 1 1" />
            </material>
            <origin rpy="0 0 0" xyz="0 0 0.075" />
        </visual>
        <collision>
            <geometry>
                <box size="0.05 0.05 0.2" />
            </geometry>
            <origin rpy="0 0 0" xyz="0 0 0.075" />
        </collision>
    </link>
    <joint name="joint3" type="revolute">
        <axis xyz="1 0 0" />
        <limit velocity="1.0" effort="30.0" upper="2.3562" lower="0" />
        <parent link="upper_arm" />
        <child link="forearm" />
        <origin rpy="0 0 0" xyz="0 0 0.15" />
    </joint>

</robot>